<?xml version="1.0" encoding="UTF-8"?>

<robot xmlns:xacro="http://www.ros.org/wiki/xacro" name="basic_outdoor_robot_wheel">
    <xacro:macro name="robot_wheel" params="wheel_prefix *joint_pose">
        <link name="${wheel_prefix}_wheel_link">
            <inertial>
                <mass value="3" />
                <origin xyz="0 0 0" />
                <inertia ixx="0.7171" ixy="0" ixz="0" iyy="0.1361" iyz="0" izz="0.7171" />
            </inertial>
            <visual>
                <origin xyz="0 0 0" rpy="${M_PI/2} 0 0" />
                <geometry>
                    <cylinder length="${wheel_width}" radius="${wheel_radius}" />
                </geometry>
                <material name="black"/>
            </visual>
            <collision>
                <origin xyz="0 0 0" rpy="${M_PI/2} 0 0" />
                <geometry>
                    <cylinder length="${wheel_width}" radius="${wheel_radius}" />
                </geometry>
            </collision>
        </link>

        <joint name="${wheel_prefix}_wheel" type="continuous">
            <parent link="base_link"/>
            <child link="${wheel_prefix}_wheel_link"/>
            <xacro:insert_block name="joint_pose"/>
            <axis xyz="0 1 0" rpy="0 0 0" />
        </joint>
    </xacro:macro>
    
</robot>