<?xml version="1.0" ?>
<!-- =================================================================================== -->
<!-- |    This document was autogenerated by xacro from src/basic_outdoor_robot_description/urdf/basic_outdoor_robot.urdf.xacro | -->
<!-- |    EDITING THIS FILE BY HAND IS NOT RECOMMENDED                                 | -->
<!-- =================================================================================== -->
<robot name="basic_outdoor_robot">
  <material name="blue">
    <color rgba="0 0 0.8 1"/>
  </material>
  <material name="black">
    <color rgba="0 0 0 1"/>
  </material>
  <material name="white">
    <color rgba="1 1 1 1"/>
  </material>
  <!-- Base Link -->
  <link name="base_link">
    <visual>
      <origin rpy="0 0 0" xyz="0 0 0"/>
      <geometry>
        <box size="0.672 0.4155 0.19"/>
      </geometry>
      <material name="blue"/>
    </visual>
    <collision>
      <origin rpy="0 0 0" xyz="0 0 0"/>
      <geometry>
        <box size="0.672 0.4155 0.19"/>
      </geometry>
    </collision>
    <inertial>
      <origin rpy="0 0 0" xyz="0 0 0"/>
      <mass value="20.0"/>
      <inertia ixx="0.1816666666666667" ixy="0.0" ixz="0.0" iyy="0.8128066666666668" iyz="0.0" izz="0.8741400000000001"/>
    </inertial>
  </link>
  <!-- Base Footprint -->
  <link name="base_footprint"/>
  <joint name="base_footprint_joint" type="fixed">
    <origin rpy="0 0 0" xyz="0 0 -0.23500000000000001"/>
    <parent link="base_link"/>
    <child link="base_footprint"/>
  </joint>
  <link name="front_right_wheel_link">
    <inertial>
      <mass value="3"/>
      <origin xyz="0 0 0"/>
      <inertia ixx="0.7171" ixy="0" ixz="0" iyy="0.1361" iyz="0" izz="0.7171"/>
    </inertial>
    <visual>
      <origin rpy="1.5707963267948966 0 0" xyz="0 0 0"/>
      <geometry>
        <cylinder length="0.116" radius="0.165"/>
      </geometry>
      <material name="black"/>
    </visual>
    <collision>
      <origin rpy="1.5707963267948966 0 0" xyz="0 0 0"/>
      <geometry>
        <cylinder length="0.116" radius="0.165"/>
      </geometry>
    </collision>
  </link>
  <joint name="front_right_wheel_joint" type="continuous">
    <parent link="base_link"/>
    <child link="front_right_wheel_link"/>
    <origin rpy="0 0 0" xyz="0.249 -0.2915 -0.07"/>
    <axis rpy="0 0 0" xyz="0 1 0"/>
  </joint>
  <link name="front_left_wheel_link">
    <inertial>
      <mass value="3"/>
      <origin xyz="0 0 0"/>
      <inertia ixx="0.7171" ixy="0" ixz="0" iyy="0.1361" iyz="0" izz="0.7171"/>
    </inertial>
    <visual>
      <origin rpy="1.5707963267948966 0 0" xyz="0 0 0"/>
      <geometry>
        <cylinder length="0.116" radius="0.165"/>
      </geometry>
      <material name="black"/>
    </visual>
    <collision>
      <origin rpy="1.5707963267948966 0 0" xyz="0 0 0"/>
      <geometry>
        <cylinder length="0.116" radius="0.165"/>
      </geometry>
    </collision>
  </link>
  <joint name="front_left_wheel_joint" type="continuous">
    <parent link="base_link"/>
    <child link="front_left_wheel_link"/>
    <origin rpy="0 0 0" xyz="0.249 0.2915 -0.07"/>
    <axis rpy="0 0 0" xyz="0 1 0"/>
  </joint>
  <link name="rear_left_wheel_link">
    <inertial>
      <mass value="3"/>
      <origin xyz="0 0 0"/>
      <inertia ixx="0.7171" ixy="0" ixz="0" iyy="0.1361" iyz="0" izz="0.7171"/>
    </inertial>
    <visual>
      <origin rpy="1.5707963267948966 0 0" xyz="0 0 0"/>
      <geometry>
        <cylinder length="0.116" radius="0.165"/>
      </geometry>
      <material name="black"/>
    </visual>
    <collision>
      <origin rpy="1.5707963267948966 0 0" xyz="0 0 0"/>
      <geometry>
        <cylinder length="0.116" radius="0.165"/>
      </geometry>
    </collision>
  </link>
  <joint name="rear_left_wheel_joint" type="continuous">
    <parent link="base_link"/>
    <child link="rear_left_wheel_link"/>
    <origin rpy="0 0 0" xyz="-0.249 0.2915 -0.07"/>
    <axis rpy="0 0 0" xyz="0 1 0"/>
  </joint>
  <link name="rear_right_wheel_link">
    <inertial>
      <mass value="3"/>
      <origin xyz="0 0 0"/>
      <inertia ixx="0.7171" ixy="0" ixz="0" iyy="0.1361" iyz="0" izz="0.7171"/>
    </inertial>
    <visual>
      <origin rpy="1.5707963267948966 0 0" xyz="0 0 0"/>
      <geometry>
        <cylinder length="0.116" radius="0.165"/>
      </geometry>
      <material name="black"/>
    </visual>
    <collision>
      <origin rpy="1.5707963267948966 0 0" xyz="0 0 0"/>
      <geometry>
        <cylinder length="0.116" radius="0.165"/>
      </geometry>
    </collision>
  </link>
  <joint name="rear_right_wheel_joint" type="continuous">
    <parent link="base_link"/>
    <child link="rear_right_wheel_link"/>
    <origin rpy="0 0 0" xyz="-0.249 -0.2915 -0.07"/>
    <axis rpy="0 0 0" xyz="0 1 0"/>
  </joint>
  <!-- IMU -->
  <link name="imu_link">
    <inertial>
      <mass value="0.001"/>
      <origin rpy="0 0 0" xyz="0 0 0"/>
      <inertia ixx="1e-09" ixy="0.0" ixz="0.0" iyy="1e-09" iyz="0.0" izz="1e-09"/>
    </inertial>
  </link>
  <joint name="imu_joint" type="fixed">
    <parent link="base_link"/>
    <child link="imu_link"/>
  </joint>
  <!-- ROS2 controls -->
  <ros2_control name="basic_outdoor_robot_system" type="system">
    <hardware>
      <plugin>gazebo_ros2_control/GazeboSystem</plugin>
    </hardware>
    <joint name="front_left_wheel_joint">
      <command_interface name="velocity">
        <param name="min">-1</param>
        <param name="max">1</param>
      </command_interface>
      <state_interface name="position"/>
      <state_interface name="velocity"/>
    </joint>
    <joint name="rear_left_wheel_joint">
      <command_interface name="velocity">
        <param name="min">-1</param>
        <param name="max">1</param>
      </command_interface>
      <state_interface name="position"/>
      <state_interface name="velocity"/>
    </joint>
    <joint name="front_right_wheel_joint">
      <command_interface name="velocity">
        <param name="min">-1</param>
        <param name="max">1</param>
      </command_interface>
      <state_interface name="position"/>
      <state_interface name="velocity"/>
    </joint>
    <joint name="rear_right_wheel_joint">
      <command_interface name="velocity">
        <param name="min">-1</param>
        <param name="max">1</param>
      </command_interface>
      <state_interface name="position"/>
      <state_interface name="velocity"/>
    </joint>
  </ros2_control>
  <gazebo>
    <plugin filename="libgazebo_ros2_control.so" name="gazebo_ros2_control">
      <parameters>/home/arwinder/robot_ws/install/basic_outdoor_robot_description/share/basic_outdoor_robot_description/config/control.yaml</parameters>
    </plugin>
  </gazebo>
  <gazebo references="imu_link">
    <sensor name="imu_sensor" type="imu">
      <plugin filename="libgazebo_ros_imu_sensor.so" name="imu_plugin">
        <ros>
          <remapping>~/out:imu/data_raw</remapping>
        </ros>
        <initial_orientation_as_reference>false</initial_orientation_as_reference>
      </plugin>
      <always_on>true</always_on>
      <update_rate>100</update_rate>
      <visualize>true</visualize>
    </sensor>
  </gazebo>
</robot>
